<?xml version="1.0"?>
<!-- Revolute-Revolute Manipulator -->
<robot name="puffin_twister" xmlns:xacro="http://www.ros.org/wiki/xacro">

  <!-- Constants for robot dimensions -->
  <xacro:property name="PI" value="3.1415926535897931"/>
  <xacro:property name="mass" value="0.06" /> <!-- arbitrary value for mass -->
  <xacro:property name="width" value="0.015" /> <!-- Square dimensions (widthxwidth) of beams -->
  <xacro:property name="height1" value="0.3" /> <!-- Link 1 -->
  <xacro:property name="height2" value="0.05" /> <!-- Link 2 -->
  <xacro:property name="height3" value="0.05" /> <!-- Link 3 -->
  <xacro:property name="camera_link" value="0.0125" /> <!-- Size of square 'camera' box -->
  <xacro:property name="axel_offset" value="0.0125" /> <!-- Space btw top of beam and the each joint -->

  <!-- Import all Gazebo-customization elements, including Gazebo colors -->
  <xacro:include filename="$(find pt_description)/urdf/pt.gazebo" />
  <!-- Import Rviz colors -->
  <xacro:include filename="$(find pt_description)/urdf/materials.xacro" />

  <link name="chassis">
    <collision>
      <origin xyz="0.0 -0.015 0.0615" rpy="0 0 0"/>
      <geometry>
        <box size="0.08 0.121 0.085"/>
      </geometry>
    </collision>

    <visual>
      <origin xyz="0 0 0" rpy="0 0 0"/>
      <geometry>
        <mesh filename="package://pt_description/meshes/twister_base.dae"/>
      </geometry>
      <material name="orange"/>
    </visual>

    <inertial>
      <origin xyz="0 -0.014693 0.06776" rpy="0 0 0"/>
      <mass value="0.626"/>
      <inertia ixx="6.154e-4" ixy="0.0" ixz="0.0"
               iyy="4.298e-4" iyz="0.0"
               izz="4.298e-4"/>
    </inertial>
  </link>

  <joint name="camera_holder_joint" type="fixed">
    <parent link="chassis"/>
    <child link="camera_holder"/>
    <origin xyz="0.0 0.0458 0.0488" rpy="0 0 0"/>
  </joint>

  <link name="camera_holder">
    <collision>
      <origin xyz="0.0 -0.0055 0.033" rpy="0 0 0"/>
      <geometry>
        <box size="0.037 0.011 0.066"/>
      </geometry>
    </collision>

    <visual>
      <origin xyz="0 0 0" rpy="0 0 0"/>
      <geometry>
        <mesh filename="package://pt_description/meshes/twister_camera_holder.dae"/>
      </geometry>
      <material name="orange"/>
    </visual>

    <inertial>
      <origin xyz="0 0.002 0.035" rpy="0 0 0"/>
      <mass value="0.012"/>
      <inertia ixx="3.717e-6" ixy="0.0" ixz="0.0"
               iyy="5.325e-6" iyz="0.0"
               izz="1.839e-6"/>
    </inertial>
  </link>

  <joint name="right_motor_joint" type="fixed">
    <parent link="chassis"/>
    <child link="right_motor"/>
    <origin xyz="0.0497 0.0 0.03255" rpy="0 0 0"/>
  </joint>

  <link name="right_motor">
    <collision>
      <origin xyz="-0.0185 -0.0205 0.0" rpy="0 0 0"/>
      <geometry>
        <box size="0.023 0.065 0.023"/>
      </geometry>
    </collision>

    <visual>
      <origin xyz="0 0 0" rpy="0 0 0"/>
      <geometry>
        <mesh filename="package://pt_description/meshes/twister_motor.dae"/>
      </geometry>
      <material name="orange"/>
    </visual>

    <inertial>
      <origin xyz="-0.0185 -0.0183 0.0" rpy="0 0 0"/>
      <mass value="0.025"/>
      <inertia ixx="9.2e-6" ixy="0.0" ixz="0.0"
               iyy="1.7e-6" iyz="0.0"
               izz="9.0e-6"/>
    </inertial>
  </link>

  <joint name="left_motor_joint" type="fixed">
    <parent link="chassis"/>
    <child link="left_motor"/>
    <origin xyz="-0.0497 0.0 0.03255" rpy="0 3.14159 0"/>
  </joint>

  <link name="left_motor">
    <collision>
      <origin xyz="-0.0185 -0.0205 0.0" rpy="0 0 0"/>
      <geometry>
        <box size="0.023 0.065 0.023"/>
      </geometry>
    </collision>

    <visual>
      <origin xyz="0 0 0" rpy="0 0 0"/>
      <geometry>
        <mesh filename="package://pt_description/meshes/twister_motor.dae"/>
      </geometry>
      <material name="orange"/>
    </visual>

    <inertial>
      <origin xyz="-0.0185 -0.0183 0.0" rpy="0 0 0"/>
      <mass value="0.025"/>
      <inertia ixx="9.2e-6" ixy="0.0" ixz="0.0"
               iyy="1.7e-6" iyz="0.0"
               izz="9.0e-6"/>
    </inertial>
  </link>

  <joint name="battery_holder_front_joint" type="fixed">
    <parent link="chassis"/>
    <child link="battery_holder_front"/>
    <origin xyz="0.0 0.0213 0.0488" rpy="0 0 3.14159"/>
  </joint>

  <link name="battery_holder_front">
    <collision>
      <origin xyz="-0.0185 -0.0205 0.0" rpy="0 0 0"/>
      <geometry>
        <box size="0.023 0.065 0.023"/>
      </geometry>
    </collision>

    <visual>
      <origin xyz="0 0 0" rpy="0 0 0"/>
      <geometry>
        <mesh filename="package://pt_description/meshes/twister_battery_holder.dae"/>
      </geometry>
      <material name="orange"/>
    </visual>

    <inertial>
      <origin xyz="0.030 -0.0089 0.0212" rpy="0 0 0"/>
      <mass value="0.011"/>
      <inertia ixx="2.0e-6" ixy="0.0" ixz="0.0"
               iyy="1.1e-5" iyz="0.0"
               izz="9.4e-6"/>
    </inertial>
  </link>

  <joint name="battery_holder_back_joint" type="fixed">
    <parent link="chassis"/>
    <child link="battery_holder_back"/>
    <origin xyz="0.0 -0.0517 0.0488" rpy="0 0 0"/>
  </joint>

  <link name="battery_holder_back">
    <collision>
      <origin xyz="-0.0185 -0.0205 0.0" rpy="0 0 0"/>
      <geometry>
        <box size="0.023 0.065 0.023"/>
      </geometry>
    </collision>

    <visual>
      <origin xyz="0 0 0" rpy="0 0 0"/>
      <geometry>
        <mesh filename="package://pt_description/meshes/twister_battery_holder.dae"/>
      </geometry>
      <material name="orange"/>
    </visual>

    <inertial>
      <origin xyz="0.030 -0.0089 0.0212" rpy="0 0 0"/>
      <mass value="0.011"/>
      <inertia ixx="2.0e-6" ixy="0.0" ixz="0.0"
               iyy="1.1e-5" iyz="0.0"
               izz="9.4e-6"/>
    </inertial>
  </link>

  <joint name="back_wheel_holder_hinge" type="continuous">
    <parent link="chassis"/>
    <child link="back_wheel_holder"/>
    <origin xyz="0.0 -0.0687 0.0183" rpy="0 0 0"/>
    <axis xyz="0 0 1"/>
    <dynamics damping="0.01" friction="0.01"/>
  </joint>

  <link name="back_wheel_holder">
    <collision>
      <origin xyz="0 -0.009 -0.0065" rpy="0 0 0"/>
      <geometry>
        <box size="0.012 0.024 0.013"/>
      </geometry>
    </collision>

    <visual>
      <origin xyz="0 0 0" rpy="0 0 0"/>
      <geometry>
        <mesh filename="package://pt_description/meshes/twister_back_wheel_holder.dae"/>
      </geometry>
      <material name="yellow"/>
    </visual>

    <inertial>
      <origin xyz="0 -0.008 -0.0046" rpy="0 0 0"/>
      <mass value="0.001"/>
      <inertia ixx="7.198e-8" ixy="0.0" ixz="0.0"
               iyy="3.400e-8" iyz="0.0"
               izz="8.483e-8"/>
    </inertial>
  </link>

  <joint name="back_wheel_hinge" type="continuous">
    <parent link="back_wheel_holder"/>
    <child link="back_wheel"/>
    <origin xyz="0.0 -0.016 -0.008" rpy="0 0 0"/>
    <axis xyz="1 0 0"/>
    <dynamics damping="0.01" friction="0.001"/>
  </joint>

  <link name="back_wheel">
    <collision>
      <origin xyz="0 0 0" rpy="0 1.5707 0"/>
      <geometry>
        <cylinder length="0.007" radius="0.0075"/>
      </geometry>
    </collision>

    <visual>
      <origin xyz="0 0 0" rpy="0 0 0"/>
      <geometry>
        <mesh filename="package://pt_description/meshes/twister_back_wheel.dae"/>
      </geometry>
      <material name="yellow"/>
    </visual>

    <inertial>
      <origin xyz="0 0 0" rpy="0 0 0"/>
      <mass value="0.001"/>
      <inertia ixx="2.427e-8" ixy="0.0" ixz="0.0"
               iyy="1.393e-8" iyz="0.0"
               izz="1.393e-8"/>
    </inertial>
  </link>

  <joint name="right_wheel_hinge" type="continuous">
    <parent link="chassis"/>
    <child link="right_wheel_rim"/>
    <origin xyz="0.0414 0 0.03255" rpy="0 0 0"/>
    <axis xyz="1 0 0"/>
    <dynamics damping="0.01" friction="0.001"/>
  </joint>

  <link name="right_wheel_rim">
    <collision>
      <origin xyz="0.016 0 0" rpy="0 1.5707 0"/>
      <geometry>
        <cylinder length="0.027" radius="0.032255"/>
      </geometry>
    </collision>

    <visual>
      <origin xyz="0 0 0" rpy="0 0 0"/>
      <geometry>
        <mesh filename="package://pt_description/meshes/twister_rim.dae"/>
      </geometry>
      <material name="yellow"/>
    </visual>

    <inertial>
      <origin xyz="0.0179 0 0" rpy="0 0 0"/>
      <mass value="0.010"/>
      <inertia ixx="4.210e-8" ixy="0.0" ixz="0.0"
               iyy="2.434e-8" iyz="0.0"
               izz="2.434e-8"/>
    </inertial>
  </link>

  <joint name="right_wheel_tire_mount" type="fixed">
    <parent link="right_wheel_rim"/>
    <child link="right_wheel_tire"/>
  </joint>

  <link name="right_wheel_tire">
    <collision>
      <origin xyz="0.016 0 0" rpy="0 1.5707 0"/>
      <geometry>
        <cylinder length="0.027" radius="0.032255"/>
      </geometry>
    </collision>

    <visual>
      <origin xyz="0 0 0" rpy="0 0 0"/>
      <geometry>
        <mesh filename="package://pt_description/meshes/twister_tire.dae"/>
      </geometry>
      <material name="black"/>
    </visual>

    <inertial>
      <origin xyz="0.016 0 0" rpy="0 0 0"/>
      <mass value="0.047"/>
      <inertia ixx="4.210e-5" ixy="0.0" ixz="0.0"
               iyy="2.434e-5" iyz="0.0"
               izz="2.434e-5"/>
    </inertial>
  </link>

  <joint name="left_wheel_hinge" type="continuous">
    <parent link="chassis"/>
    <child link="left_wheel_rim"/>
    <origin xyz="-0.0414 0 0.03255" rpy="0 0 3.14159"/>
    <axis xyz="1 0 0"/>
    <dynamics damping="0.01" friction="0.001"/>
  </joint>

  <link name="left_wheel_rim">
    <visual>
      <origin xyz="0 0 0" rpy="0 0 0"/>
      <geometry>
        <mesh filename="package://pt_description/meshes/twister_rim.dae"/>
      </geometry>
      <material name="yellow"/>
    </visual>

    <inertial>
      <origin xyz="0.0179 0 0" rpy="0 0 0"/>
      <mass value="0.010"/>
      <inertia ixx="4.210e-8" ixy="0.0" ixz="0.0"
               iyy="2.434e-8" iyz="0.0"
               izz="2.434e-8"/>
    </inertial>
  </link>

  <joint name="left_wheel_tire_mount" type="fixed">
    <parent link="left_wheel_rim"/>
    <child link="left_wheel_tire"/>
  </joint>

  <link name="left_wheel_tire">
    <collision>
      <origin xyz="0.016 0 0" rpy="0 1.5707 0"/>
      <geometry>
        <cylinder length="0.027" radius="0.032255"/>
      </geometry>
    </collision>

    <visual>
      <origin xyz="0 0 0" rpy="0 0 0"/>
      <geometry>
        <mesh filename="package://pt_description/meshes/twister_tire.dae"/>
      </geometry>
      <material name="black"/>
    </visual>

    <inertial>
      <origin xyz="0.016 0 0" rpy="0 0 0"/>
      <mass value="0.047"/>
      <inertia ixx="4.210e-5" ixy="0.0" ixz="0.0"
               iyy="2.434e-5" iyz="0.0"
               izz="2.434e-5"/>
    </inertial>
  </link>

  <joint name="camera_joint" type="fixed">
    <origin xyz="0 0.05 0.088" rpy="0 0 1.5707"/>
    <parent link="chassis"/>
    <child link="camera_link"/>
  </joint>

  <link name="camera_link">
    <collision>
      <origin xyz="0 0 0" rpy="0 0 0"/>
      <geometry>
        <box size="0.005 0.005 0.005"/>
      </geometry>
    </collision>

    <visual>
      <origin xyz="0 0 0" rpy="0 0 0"/>
      <geometry>
        <box size="0.005 0.005 0.005"/>
      </geometry>
      <material name="yellow"/>
    </visual>

    <inertial>
      <mass value="1e-5" />
      <origin xyz="0 0 0" rpy="0 0 0"/>
      <inertia ixx="1e-8" ixy="0" ixz="0" 
               iyy="1e-8" iyz="0" 
               izz="1e-8" />
    </inertial>
  </link>

  <joint name="camera_optical_joint" type="fixed">
    <origin xyz="0 0 0" rpy="${-PI/2} 0 ${-PI/2}"/>
    <parent link="camera_link"/>
    <child link="camera_link_optical"/>
  </joint>

  <link name="camera_link_optical">
  </link>

  <transmission name="right_wheel_transmission" type="SimpleTransmission">
    <type>transmission_interface/SimpleTransmission</type>
    <joint name="right_wheel_hinge">
      <hardwareInterface>hardware_interface/EffortJointInterface</hardwareInterface>
    </joint>
    <actuator name="right_wheel_motor">
      <mechanicalReduction>1</mechanicalReduction>
    </actuator>
  </transmission>

  <transmission name="left_wheel_transmission" type="SimpleTransmission">
    <type>transmission_interface/SimpleTransmission</type>
    <joint name="left_wheel_hinge">
      <hardwareInterface>hardware_interface/EffortJointInterface</hardwareInterface>
    </joint>
    <actuator name="left_wheel_motor">
      <mechanicalReduction>1</mechanicalReduction>
    </actuator>
  </transmission>

</robot>
