<?xml version="1.0"?>
<!-- Revolute-Revolute Manipulator -->
<robot name="puffin_twister" xmlns:xacro="http://www.ros.org/wiki/xacro">

  <!-- Constants for robot dimensions -->
  <xacro:property name="PI" value="3.1415926535897931"/>

  <!-- Import all Gazebo-customization elements, including Gazebo colors -->
  <xacro:include filename="$(find pt_description)/urdf/pt.gazebo" />
  <!-- Import Rviz colors -->
  <xacro:include filename="$(find pt_description)/urdf/materials.xacro" />

  
  <link name="base_link"/>
  
  <joint name="chassis_joint" type="fixed">
    <origin xyz="0.0 0.0 0.002"/>
    <parent link="base_link"/>
    <child link="chassis"/>
  </joint>

  <link name="chassis">
    <visual>
      <origin xyz="0 0 0" rpy="0 0 0"/>
      <geometry>
        <mesh filename="package://pt_description/meshes/twister_base.dae"/>
      </geometry>
      <material name="orange"/>
    </visual>

    <collision>
      <origin xyz="0.5 -0.015 0.062" rpy="0 0 0"/>
      <geometry>
        <box size="0.08 0.121 0.181"/>
      </geometry>
    </collision>

    <inertial>
      <origin xyz="0 -0.014693 0.06776" rpy="0 0 0"/>
      <mass value="0.626"/>
      <inertia ixx="6.154e-4" ixy="0.0" ixz="0.0"
               iyy="4.298e-4" iyz="0.0"
               izz="4.298e-4"/>
    </inertial>
  </link>

  <joint name="right_wheel_hinge" type="continuous">
    <parent link="chassis"/>
    <child link="right_wheel_rim"/>
    <origin xyz="0.0414 0 0.03255" rpy="0 0 0"/>
    <axis xyz="1 0 0"/>
    <dynamics damping="0.7" friction="0.0"/>
  </joint>

  <link name="right_wheel_rim">
    <collision>
      <origin xyz="0.017 0 0" rpy="0 1.5707 0"/>
      <geometry>
        <cylinder length="0.026" radius="0.032255"/>
      </geometry>
    </collision>

    <visual>
      <origin xyz="0 0 0" rpy="0 0 0"/>
      <geometry>
        <mesh filename="package://pt_description/meshes/twister_rim.dae"/>
      </geometry>
      <material name="yellow"/>
    </visual>

    <inertial>
      <origin xyz="0.0179 0 0" rpy="0 0 0"/>
      <mass value="0.010"/>
      <inertia ixx="4.210e-8" ixy="0.0" ixz="0.0"
               iyy="2.434e-8" iyz="0.0"
               izz="2.434e-8"/>
    </inertial>
  </link>

  <joint name="right_wheel_tire_mount" type="fixed">
    <parent link="right_wheel_rim"/>
    <child link="right_wheel_tire"/>
  </joint>

  <link name="right_wheel_tire">
    <collision>
      <origin xyz="0.017 0 0" rpy="0 1.5707 0"/>
      <geometry>
        <cylinder length="0.026" radius="0.032255"/>
      </geometry>
    </collision>

    <visual>
      <origin xyz="0 0 0" rpy="0 0 0"/>
      <geometry>
        <mesh filename="package://pt_description/meshes/twister_tire.dae"/>
      </geometry>
      <material name="black"/>
    </visual>

    <inertial>
      <origin xyz="0.0179 0 0" rpy="0 0 0"/>
      <mass value="0.057"/>
      <inertia ixx="4.210e-5" ixy="0.0" ixz="0.0"
               iyy="2.434e-5" iyz="0.0"
               izz="2.434e-5"/>
    </inertial>
  </link>

  <joint name="left_wheel_hinge" type="continuous">
    <parent link="chassis"/>
    <child link="left_wheel_rim"/>
    <origin xyz="-0.0414 0 0.03255" rpy="0 0 3.14159"/>
    <axis xyz="1 0 0"/>
    <dynamics damping="0.7" friction="0"/>
  </joint>

  <link name="left_wheel_rim">
    <collision>
      <origin xyz="0.017 0 0" rpy="0 1.5707 0"/>
      <geometry>
        <cylinder length="0.026" radius="0.032255"/>
      </geometry>
    </collision>
    
    <visual>
      <origin xyz="0 0 0" rpy="0 0 0"/>
      <geometry>
        <mesh filename="package://pt_description/meshes/twister_rim.dae"/>
      </geometry>
      <material name="yellow"/>
    </visual>

    <inertial>
      <origin xyz="0.0179 0 0" rpy="0 0 0"/>
      <mass value="0.010"/>
      <inertia ixx="4.210e-8" ixy="0.0" ixz="0.0"
               iyy="2.434e-8" iyz="0.0"
               izz="2.434e-8"/>
    </inertial>
  </link>

  <joint name="left_wheel_tire_mount" type="fixed">
    <parent link="left_wheel_rim"/>
    <child link="left_wheel_tire"/>
  </joint>

  <link name="left_wheel_tire">
    <collision>
      <origin xyz="0.017 0 0" rpy="0 1.5707 0"/>
      <geometry>
        <cylinder length="0.026" radius="0.032255"/>
      </geometry>
    </collision>

    <visual>
      <origin xyz="0 0 0" rpy="0 0 0"/>
      <geometry>
        <mesh filename="package://pt_description/meshes/twister_tire.dae"/>
      </geometry>
      <material name="black"/>
    </visual>

    <inertial>
      <origin xyz="0.0179 0 0" rpy="0 0 0"/>
      <mass value="0.057"/>
      <inertia ixx="4.210e-5" ixy="0.0" ixz="0.0"
               iyy="2.434e-5" iyz="0.0"
               izz="2.434e-5"/>
    </inertial>
  </link>


  <joint name="camera_joint" type="fixed">
    <axis xyz="0 1 0" />
    <origin xyz="0 0.045 0.090" rpy="0 0 0"/>
    <parent link="chassis"/>
    <child link="camera_link"/>
  </joint>

  <link name="camera_link">
    <collision>
      <origin xyz="0 0 0" rpy="0 0 0"/>
      <geometry>
        <box size="0.005 0.005 0.005"/>
      </geometry>
    </collision>

    <visual>
      <origin xyz="0 0 0" rpy="0 0 0"/>
      <geometry>
        <box size="0.005 0.005 0.005"/>
      </geometry>
      <material name="red"/>
    </visual>

    <inertial>
      <mass value="1e-5" />
      <origin xyz="0 0 0" rpy="0 0 0"/>
      <inertia ixx="1e-8" ixy="0" ixz="0" 
               iyy="1e-8" iyz="0" 
               izz="1e-8" />
    </inertial>
  </link>

  <!-- generate an optical frame http://www.ros.org/reps/rep-0103.html#suffix-frames
      so that ros and opencv can operate on the camera frame correctly -->
  <joint name="camera_optical_joint" type="fixed">
    <!-- these values have to be these values otherwise the gazebo camera image
        won't be aligned properly with the frame it is supposedly originating from -->
    <origin xyz="0 0 0" rpy="${-pi/2} 0 ${-pi/2}"/>
    <parent link="camera_link"/>
    <child link="camera_link_optical"/>
  </joint>

  <link name="camera_link_optical">
  </link>

  <transmission name="right_wheel_transmission" type="SimpleTransmission">
    <type>transmission_interface/SimpleTransmission</type>
    <joint name="right_wheel_hinge">
      <hardwareInterface>hardware_interface/EffortJointInterface</hardwareInterface>
    </joint>
    <actuator name="right_wheel_motor">
      <mechanicalReduction>48</mechanicalReduction>
    </actuator>
  </transmission>

  <transmission name="left_wheel_transmission" type="SimpleTransmission">
    <type>transmission_interface/SimpleTransmission</type>
    <joint name="left_wheel_hinge">
      <hardwareInterface>hardware_interface/EffortJointInterface</hardwareInterface>
    </joint>
    <actuator name="left_wheel_motor">
      <mechanicalReduction>48</mechanicalReduction>
    </actuator>
  </transmission>


</robot>