<?xml version='1.0'?>
<sdf version='1.4'>
  <model name="twister">
    <static>false</static>
    <pose>0 0 0.01 0 0 0</pose>

    <link name='chassis'>

      <visual name="twister_base">
        <geometry>
          <mesh><uri>file:///home/jst/development/puffin-pilot/twister/gazebo/twister_base.dae</uri></mesh>
        </geometry>
        <material>
          <script>
            <uri>file://media/materials/scripts/gazebo.material</uri>
            <name>Gazebo/DarkGrey</name>
          </script>
        </material>
      </visual>

      <visual name="twister_camera_holder">
        <pose>0 0.0448 0.0488 0 0 0</pose>
        <geometry>
          <mesh><uri>file:///home/jst/development/puffin-pilot/twister/gazebo/twister_camera_holder.dae</uri></mesh>
        </geometry>
        <material>
          <script>
            <uri>file://media/materials/scripts/gazebo.material</uri>
            <name>Gazebo/DarkGrey</name>
          </script>
        </material>
      </visual>

      <visual name="twister_battery_holder_front">
        <pose>0 0.0213 0.0488 0 0 3.14159</pose>
        <geometry>
          <mesh><uri>file:///home/jst/development/puffin-pilot/twister/gazebo/twister_battery_holder.dae</uri></mesh>
        </geometry>
        <material>
          <script>
            <uri>file://media/materials/scripts/gazebo.material</uri>
            <name>Gazebo/DarkGrey</name>
          </script>
        </material>
      </visual>

      <visual name="twister_battery_holder_back">
        <pose>0 -0.0517 0.0488 0 0 0</pose>
        <geometry>
          <mesh><uri>file:///home/jst/development/puffin-pilot/twister/gazebo/twister_battery_holder.dae</uri></mesh>
        </geometry>
        <material>
          <script>
            <uri>file://media/materials/scripts/gazebo.material</uri>
            <name>Gazebo/DarkGrey</name>
          </script>
        </material>
      </visual>

      <visual name="twister_motor_right">
        <pose>0.0497 0 0.03255 0 0 0</pose>
        <geometry>
          <mesh><uri>file:///home/jst/development/puffin-pilot/twister/gazebo/twister_motor.dae</uri></mesh>
        </geometry>
        <material>
          <script>
            <uri>file://media/materials/scripts/gazebo.material</uri>
            <name>Gazebo/DarkGrey</name>
          </script>
        </material>
      </visual>

      <visual name="twister_motor_left">
        <pose>-0.0497 0 0.03255 0 3.14159 0</pose>
        <geometry>
          <mesh><uri>file:///home/jst/development/puffin-pilot/twister/gazebo/twister_motor.dae</uri></mesh>
        </geometry>
        <material>
          <script>
            <uri>file://media/materials/scripts/gazebo.material</uri>
            <name>Gazebo/DarkGrey</name>
          </script>
        </material>
      </visual>

    </link>

    <link name='back_wheel'>
      <pose>0.0 -0.0687 0.0183 0 0 0</pose>

      <collision name="collision">
        <pose>0 -0.016 -0.008 0 1.5707 0</pose>
        <geometry>
          <cylinder>
            <radius>.01</radius>
            <length>.003</length>
          </cylinder>
        </geometry>
      </collision>

      <visual name="twister_back_wheel">
        <geometry>
          <mesh><uri>file:///home/jst/development/puffin-pilot/twister/gazebo/twister_back_wheel.dae</uri></mesh>
        </geometry>
        <material>
          <script>
            <uri>file://media/materials/scripts/gazebo.material</uri>
            <name>Gazebo/DarkGrey</name>
          </script>
        </material>
      </visual>

    </link>

    <link name='wheel_right'>
      <pose>0.0414 0 0.03255 0 0 0</pose>

      <collision name="collision">
        <pose>0.017 0 0 0 1.5707 0</pose>
        <geometry>
          <cylinder>
            <radius>.032255</radius>
            <length>.026</length>
          </cylinder>
        </geometry>
      </collision>

      <visual name="twister_rim_right">
        <geometry>
          <mesh><uri>file:///home/jst/development/puffin-pilot/twister/gazebo/twister_rim.dae</uri></mesh>
        </geometry>
        <material>
          <script>
            <uri>file://media/materials/scripts/gazebo.material</uri>
            <name>Gazebo/DarkYellow</name>
          </script>
        </material>
      </visual>

      <visual name="twister_tire_right">
        <geometry>
          <mesh><uri>file:///home/jst/development/puffin-pilot/twister/gazebo/twister_tire.dae</uri></mesh>
        </geometry>
        <material>
          <script>
            <uri>file://media/materials/scripts/gazebo.material</uri>
            <name>Gazebo/DarkGrey</name>
          </script>
        </material>
      </visual>

    </link>

    <link name='wheel_left'>

      <pose>-0.0414 0 0.03255 0 0 3.14159</pose>

      <collision name="collision">
        <pose>0.017 0 0 0 1.5707 0</pose>
        <geometry>
          <cylinder>
            <radius>.032255</radius>
            <length>.026</length>
          </cylinder>
        </geometry>
      </collision>

      <visual name="twister_rim_left">
        <geometry>
          <mesh><uri>file:///home/jst/development/puffin-pilot/twister/gazebo/twister_rim.dae</uri></mesh>
        </geometry>
        <material>
          <script>
            <uri>file://media/materials/scripts/gazebo.material</uri>
            <name>Gazebo/DarkYellow</name>
          </script>
        </material>
      </visual>

      <visual name="twister_tire_left">
        <geometry>
          <mesh><uri>file:///home/jst/development/puffin-pilot/twister/gazebo/twister_tire.dae</uri></mesh>
        </geometry>
        <material>
          <script>
            <uri>file://media/materials/scripts/gazebo.material</uri>
            <name>Gazebo/DarkGrey</name>
          </script>
        </material>
      </visual>

    </link>

    <joint type="revolute" name="right_wheel_hinge">
      <pose>0 0 0 0 0 0</pose>
      <child>wheel_right</child>
      <parent>chassis</parent>
      <axis>
        <xyz>-1 0 0</xyz>
      </axis>
    </joint>

    <joint type="revolute" name="left_wheel_hinge">
      <pose>0 0 0 0 0 0</pose>
      <child>wheel_left</child>
      <parent>chassis</parent>
      <axis>
        <xyz>-1 0 0</xyz>
      </axis>
    </joint>

    <joint type="revolute" name="back_wheel_hinge">
      <pose>0 0 0 0 0 0</pose>
      <child>back_wheel</child>
      <parent>chassis</parent>
      <axis>
        <xyz>0 0 1</xyz>
      </axis>
    </joint>

  </model>
</sdf>


